Workbook

Sheet README
A1: MCED District Account Assistant — Practice Performance Tracker
A2: Practice scoring rule (NOT an official MCED scheme): 1 mark per correct answer, 0 for wrong/unanswered, no negative marking (change only if you deliberately configure another rule).
A4: HOW TO USE (tutor only — this workbook contains the answer key):
A5: 1. Candidate solves the question-only paper without the answer key; tutor records the answers.
A6: 2. Sheet "Attempts": add one row per attempt. Fill the yellow cells: Attempt ID (e.g. A001), Candidate, Date, Paper No (1-11), then the candidate's responses A/B/C/D in Q1..Q30 (leave blank = unanswered).
A7: 3. Green cells calculate automatically: attempted / correct / incorrect / unanswered / score / %.
A8: 4. Sheet "Topic_Accuracy": topic-wise accuracy per attempt, weakest subtopic and recommended remedial lesson.
A9: 5. Sheet "Error_Log": for each wrong answer, choose an error category (Conceptual / Calculation / Terminology / Careless).
A10: 6. Teach the recommended lesson (Remediation Notes), give a short remedial quiz, then record the retest as a new Attempt and link both IDs in sheet "Retest".
A11: 7. Sheet "Baseline_40": enter the candidate's 40 baseline answers for section-wise baseline analysis.
A13: Do NOT label the candidate weak/strong from total score alone; use topic-wise accuracy (suggested guide, not an official cutoff): <50% re-teach, 50-74% practice, >=75% relatively secure. Use topic % only when the subtopic has at least 3 questions.
A14: Rows 2..200 of Attempts are pre-formulated. Copy a row down if you need more.

Sheet Papers
A1: Paper No | B1: Title | C1: Questions | D1: Minutes | E1: Sub1 | F1: Sub2 | G1: Sub3 | H1: Sub4 | I1: Sub5 | J1: Sub6 | K1: Les1 | L1: Les2 | M1: Les3 | N1: Les4 | O1: Les5 | P1: Les6
A2: 1 | B2: Baseline Test Analysis and Remediation | C2: 25 | D2: 35 | E2: A Bookkeeping & Basic Accounting | F2: B Taxation | G2: C Budget & Financial Discipline | H2: D Banking | I2: E Computer & Modern Tools | J2: F Current Affairs / General Awareness | K2: Papers 2–5 (Accounting) | L2: Paper 6 (Taxation) | M2: Paper 7 (Budget) | N2: Paper 8 (Banking) | O2: Paper 9 (Computer/Excel) | P2: Paper 10 (Current Affairs)
A3: 2 | B3: Accounting Fundamentals and Accounting Equation | C3: 23 | D3: 30 | E3: Book-keeping, Accounting आणि Users | F3: Accounts चे प्रकार (Classification) | G3: Accounting Concepts | H3: Accounting Equation | I3: Transactions चा Equation वर परिणाम | K3: Lesson 2.1 Book-keeping vs Accounting | L3: Lesson 2.2 Assets-Liabilities-Capital-Income-Expense | M3: Lesson 2.3 Basic Accounting Concepts | N3: Lesson 2.4 A = L + C सूत्र | O3: Lesson 2.5 Transaction analysis (equation drill)
A4: 3 | B4: Debit, Credit and Journal Entries | C4: 24 | D4: 35 | E4: Golden Rules (Personal/Real/Nominal) | F4: Debit-Credit चा परिणाम | G4: Basic Journal Entries (cash) | H4: Credit व्यवहार, Returns, Discount | I4: Adjustment/Special Entries | J4: Journal Format आणि Terminology | K4: Lesson 3.1 Three Golden Rules | L4: Lesson 3.2 Dr/Cr rule table | M4: Lesson 3.3 Cash transaction journal drill | N4: Lesson 3.4 Credit, Returns, Discount entries | O4: Lesson 3.5 Drawings, Outstanding, Prepaid, Bad debts | P4: Lesson 3.6 Journal format
A5: 4 | B5: Ledger, Cash Book and Trial Balance | C5: 24 | D5: 35 | E5: Ledger posting आणि balancing | F5: Cash Book (single/three column, contra) | G5: Petty Cash / Imprest | H5: Trial Balance आणि errors | I5: Subsidiary Books (Purchases/Sales/Returns) | K5: Lesson 4.1 Ledger T-account आणि balancing | L5: Lesson 4.2 Cash Book प्रकार | M5: Lesson 4.3 Imprest system | N5: Lesson 4.4 Trial Balance व errors | O5: Lesson 4.5 Subsidiary books
A6: 5 | B6: Bank Reconciliation, Depreciation and Final Accounts | C6: 24 | D6: 40 | E6: Bank Reconciliation Statement (BRS) | F6: Depreciation (SLM / WDV) | G6: Trading Account | H6: Profit & Loss Account | I6: Balance Sheet | J6: Adjustments (Outstanding, Prepaid, Bad debts) | K6: Lesson 5.1 BRS step-by-step | L6: Lesson 5.2 Depreciation methods | M6: Lesson 5.3 Trading A/c व Gross Profit | N6: Lesson 5.4 P&L A/c व Net Profit | O6: Lesson 5.5 Balance Sheet मांडणी | P6: Lesson 5.6 Year-end adjustments
A7: 6 | B7: Taxation: GST, Input Tax Credit, TDS and Income Tax Basics | C7: 24 | D7: 35 | E7: GST रचना आणि दर | F7: GST गणना आणि ITC | G7: GST documents/returns | H7: TDS | I7: Income Tax basics | K7: Lesson 6.1 GST structure (CGST/SGST/IGST/rates) | L7: Lesson 6.2 GST calculation आणि ITC set-off | M7: Lesson 6.3 GSTIN, invoice, returns | N7: Lesson 6.4 TDS concept आणि गणना | O7: Lesson 6.5 Income tax basics
A8: 7 | B8: Budget and Financial Discipline | C8: 22 | D8: 30 | E8: Budget basics | F8: Capital vs Revenue (expenditure/receipts) | G8: Budget variance आणि utilisation | H8: Government Budget concepts (deficits, Articles) | I8: Financial discipline आणि internal control | K8: Lesson 7.1 Budget म्हणजे काय | L8: Lesson 7.2 Capital vs Revenue | M8: Lesson 7.3 Variance व grant utilisation | N8: Lesson 7.4 Deficits व Constitution चे Articles | O8: Lesson 7.5 Vouchers, controls, segregation of duties
A9: 8 | B9: Banking and Digital Payment Systems | C9: 22 | D9: 30 | E9: RBI आणि Banking structure | F9: Bank accounts आणि KYC | G9: Cheque आणि Negotiable instruments | H9: NEFT/RTGS/IMPS/UPI | I9: Digital safety आणि fraud | J9: Interest आणि bank calculations | K9: Lesson 8.1 RBI functions, Repo, CRR | L9: Lesson 8.2 Account types, KYC | M9: Lesson 8.3 Cheque basics | N9: Lesson 8.4 NEFT vs RTGS vs IMPS vs UPI | O9: Lesson 8.5 Digital safety | P9: Lesson 8.6 Interest calculation
A10: 9 | B10: Computer Knowledge, Excel and Modern Office Tools | C10: 22 | D10: 30 | E10: Computer basics (hardware/software) | F10: Windows, files आणि shortcuts | G10: Word, Email आणि PDF | H10: Excel basics आणि functions | I10: Excel application (SUMIF, VLOOKUP, %) | J10: Internet, cloud, cyber safety आणि modern tools | K10: Lesson 9.1 Hardware-Software-Memory | L10: Lesson 9.2 Windows आणि shortcuts | M10: Lesson 9.3 Word/Email | N10: Lesson 9.4 Excel functions | O10: Lesson 9.5 Excel लेखा उदाहरणे | P10: Lesson 9.6 Cloud आणि सुरक्षा
A11: 10 | B11: Current Affairs and General Awareness | C11: 22 | D11: 30 | E11: स्थिर General Knowledge (संविधान, संस्था) | F11: Union Budget 2026-27 | G11: Maharashtra Budget 2026-27 आणि राज्य | H11: Taxation/Banking updates | I11: Census 2027 आणि इतर घडामोडी | K11: Lesson 10.1 Static GK (Articles, संस्था, तारखा) | L11: Lesson 10.2 Union Budget 2026-27 आकडे | M11: Lesson 10.3 Maharashtra Budget 2026-27 | N11: Lesson 10.4 GST 2.0, Income-tax Act 2025, RBI | O11: Lesson 10.5 Census 2027
A12: 11 | B12: Comprehensive Mixed Mock Test | C12: 30 | D12: 40 | E12: A Bookkeeping & Accounting | F12: B Taxation | G12: C Budget & Financial Discipline | H12: D Banking | I12: E Computer & Excel | J12: F Current Affairs / General Awareness | K12: Papers 2–5 | L12: Paper 6 | M12: Paper 7 | N12: Paper 8 | O12: Paper 9 | P12: Paper 10

Sheet Key
A1: Paper | B1: Q | C1: Answer | D1: Subtopic# | E1: Subtopic | F1: Level | G1: ID(P*100+Q)
A2: 1 | B2: 1 | C2: B | D2: 1 | E2: A Bookkeeping & Basic Accounting | F2: Foundational | G2: 101
A3: 1 | B3: 2 | C3: A | D3: 1 | E3: A Bookkeeping & Basic Accounting | F3: Foundational | G3: 102
A4: 1 | B4: 3 | C4: D | D4: 2 | E4: B Taxation | F4: Foundational | G4: 103
A5: 1 | B5: 4 | C5: C | D5: 3 | E5: C Budget & Financial Discipline | F5: Foundational | G5: 104
A6: 1 | B6: 5 | C6: B | D6: 4 | E6: D Banking | F6: Foundational | G6: 105
A7: 1 | B7: 6 | C7: D | D7: 5 | E7: E Computer & Modern Tools | F7: Foundational | G7: 106
A8: 1 | B8: 7 | C8: A | D8: 5 | E8: E Computer & Modern Tools | F8: Foundational | G8: 107
A9: 1 | B9: 8 | C9: C | D9: 6 | E9: F Current Affairs / General Awareness | F9: Foundational | G9: 108
A10: 1 | B10: 9 | C10: C | D10: 1 | E10: A Bookkeeping & Basic Accounting | F10: Intermediate | G10: 109
A11: 1 | B11: 10 | C11: A | D11: 1 | E11: A Bookkeeping & Basic Accounting | F11: Intermediate | G11: 110
A12: 1 | B12: 11 | C12: D | D12: 1 | E12: A Bookkeeping & Basic Accounting | F12: Intermediate | G12: 111
A13: 1 | B13: 12 | C13: B | D13: 2 | E13: B Taxation | F13: Intermediate | G13: 112
... A263: 11 | B263: 30 | C263: A | D263: 6 | E263: F Current Affairs / General Awareness | F263: Application | G263: 1130

Sheet SubMap
A1: Paper | B1: Q1 | C1: Q2 | D1: Q3 | E1: Q4 | F1: Q5 | G1: Q6 | H1: Q7 | I1: Q8 | J1: Q9 | K1: Q10 | L1: Q11 | M1: Q12 | N1: Q13 | O1: Q14 | P1: Q15 | Q1: Q16 | R1: Q17 | S1: Q18 | T1: Q19 | U1: Q20 | V1: Q21 | W1: Q22 | X1: Q23 | Y1: Q24 | Z1: Q25 | AA1: Q26 | AB1: Q27 | AC1: Q28 | AD1: Q29 | AE1: Q30
A2: 1 | B2: 1 | C2: 1 | D2: 2 | E2: 3 | F2: 4 | G2: 5 | H2: 5 | I2: 6 | J2: 1 | K2: 1 | L2: 1 | M2: 2 | N2: 2 | O2: 3 | P2: 4 | Q2: 4 | R2: 5 | S2: 6 | T2: 1 | U2: 1 | V2: 2 | W2: 3 | X2: 4 | Y2: 5 | Z2: 6
A3: 2 | B3: 1 | C3: 1 | D3: 2 | E3: 2 | F3: 2 | G3: 2 | H3: 4 | I3: 3 | J3: 3 | K3: 3 | L3: 3 | M3: 5 | N3: 4 | O3: 4 | P3: 4 | Q3: 5 | R3: 5 | S3: 5 | T3: 2 | U3: 5 | V3: 4 | W3: 4 | X3: 5
A4: 3 | B4: 1 | C4: 1 | D4: 1 | E4: 2 | F4: 2 | G4: 2 | H4: 6 | I4: 6 | J4: 3 | K4: 3 | L4: 4 | M4: 4 | N4: 4 | O4: 4 | P4: 5 | Q4: 5 | R4: 5 | S4: 3 | T4: 4 | U4: 2 | V4: 3 | W4: 5 | X4: 4 | Y4: 4
A5: 4 | B5: 1 | C5: 1 | D5: 1 | E5: 2 | F5: 2 | G5: 4 | H5: 4 | I5: 5 | J5: 1 | K5: 1 | L5: 2 | M5: 2 | N5: 2 | O5: 3 | P5: 4 | Q5: 4 | R5: 5 | S5: 4 | T5: 4 | U5: 2 | V5: 1 | W5: 5 | X5: 3 | Y5: 4
A6: 5 | B6: 1 | C6: 1 | D6: 2 | E6: 2 | F6: 3 | G6: 4 | H6: 5 | I6: 3 | J6: 1 | K6: 1 | L6: 2 | M6: 2 | N6: 3 | O6: 4 | P6: 6 | Q6: 6 | R6: 5 | S6: 6 | T6: 2 | U6: 1 | V6: 4 | W6: 5 | X6: 3 | Y6: 2
A7: 6 | B7: 1 | C7: 1 | D7: 1 | E7: 1 | F7: 2 | G7: 3 | H7: 4 | I7: 5 | J7: 2 | K7: 2 | L7: 2 | M7: 2 | N7: 3 | O7: 2 | P7: 4 | Q7: 4 | R7: 5 | S7: 2 | T7: 2 | U7: 4 | V7: 1 | W7: 2 | X7: 5 | Y7: 5
A8: 7 | B8: 1 | C8: 4 | D8: 2 | E8: 2 | F8: 4 | G8: 5 | H8: 5 | I8: 3 | J8: 3 | K8: 4 | L8: 4 | M8: 4 | N8: 2 | O8: 4 | P8: 5 | Q8: 1 | R8: 3 | S8: 3 | T8: 2 | U8: 5 | V8: 4 | W8: 4
A9: 8 | B9: 1 | C9: 1 | D9: 2 | E9: 2 | F9: 3 | G9: 4 | H9: 4 | I9: 5 | J9: 4 | K9: 3 | L9: 1 | M9: 1 | N9: 4 | O9: 4 | P9: 2 | Q9: 3 | R9: 6 | S9: 6 | T9: 6 | U9: 4 | V9: 5 | W9: 6
A10: 9 | B10: 1 | C10: 1 | D10: 2 | E10: 2 | F10: 3 | G10: 3 | H10: 4 | I10: 4 | J10: 4 | K10: 4 | L10: 5 | M10: 5 | N10: 4 | O10: 6 | P10: 6 | Q10: 2 | R10: 5 | S10: 5 | T10: 4 | U10: 5 | V10: 6 | W10: 6
A11: 10 | B11: 2 | C11: 1 | D11: 1 | E11: 4 | F11: 1 | G11: 1 | H11: 1 | I11: 4 | J11: 2 | K11: 2 | L11: 2 | M11: 2 | N11: 3 | O11: 3 | P11: 5 | Q11: 5 | R11: 3 | S11: 3 | T11: 2 | U11: 4 | V11: 4 | W11: 5
A12: 11 | B12: 1 | C12: 1 | D12: 1 | E12: 2 | F12: 3 | G12: 4 | H12: 4 | I12: 5 | J12: 5 | K12: 6 | L12: 1 | M12: 1 | N12: 1 | O12: 1 | P12: 2 | Q12: 2 | R12: 3 | S12: 3 | T12: 4 | U12: 4 | V12: 5 | W12: 6 | X12: 1 | Y12: 1 | Z12: 1 | AA12: 2 | AB12: 3 | AC12: 4 | AD12: 5 | AE12: 6

Sheet Attempts
A1: Attempt ID | B1: Candidate | C1: Date | D1: Paper No | E1: Topic | F1: Total Qs | G1: Attempted | H1: Correct | I1: Incorrect | J1: Unanswered | K1: Score | L1: % | M1: Q1 | N1: Q2 | O1: Q3 | P1: Q4 | Q1: Q5 | R1: Q6 | S1: Q7 | T1: Q8 | U1: Q9 | V1: Q10 | W1: Q11 | X1: Q12 | Y1: Q13 | Z1: Q14 | AA1: Q15 | AB1: Q16 | AC1: Q17 | AD1: Q18 | AE1: Q19 | AF1: Q20 | AG1: Q21 | AH1: Q22 | AI1: Q23 | AJ1: Q24 | AK1: Q25 | AL1: Q26 | AM1: Q27 | AN1: Q28 | AO1: Q29 | AP1: Q30 | AQ1: → flags | AR1: f1 | AS1: f2 | AT1: f3 | AU1: f4 | AV1: f5 | AW1: f6 | AX1: f7 | AY1: f8 | AZ1: f9 | BA1: f10 | BB1: f11 | BC1: f12 | BD1: f13 | BE1: f14 | BF1: f15 | BG1: f16 | BH1: f17 | BI1: f18 | BJ1: f19 | BK1: f20 | BL1: f21 | BM1: f22 | BN1: f23 | BO1: f24 | BP1: f25 | BQ1: f26 | BR1: f27 | BS1: f28 | BT1: f29 | BU1: f30
E2: =IF($D2="","",IFERROR(INDEX(Papers!$B$2:$B$12,MATCH($D2,Papers!$A$2:$A$12,0)),"?")) | F2: =IF($D2="","",IFERROR(INDEX(Papers!$C$2:$C$12,MATCH($D2,Papers!$A$2:$A$12,0)),0)) | G2: =IF($D2="","",COUNTIF(M2:AP2,"?*")) | H2: =IF($D2="","",SUM(AR2:BU2)) | I2: =IF($D2="","",G2-H2) | J2: =IF($D2="","",F2-G2) | K2: =IF($D2="","",H2) | L2: =IF($D2="","",IF(F2=0,"",ROUND(H2/F2*100,1))) | AR2: =IF(OR($D2="",M2="",1>$F2),0,IF(UPPER(TRIM(M2))=IFERROR(INDEX(Key!$C$2:$C$263,MATCH($D2*100+1,Key!$G$2:$G$263,0)),"#"),1,0)) | AS2: =IF(OR($D2="",N2="",2>$F2),0,IF(UPPER(TRIM(N2))=IFERROR(INDEX(Key!$C$2:$C$263,MATCH($D2*100+2,Key!$G$2:$G$263,0)),"#"),1,0)) | AT2: =IF(OR($D2="",O2="",3>$F2),0,IF(UPPER(TRIM(O2))=IFERROR(INDEX(Key!$C$2:$C$263,MATCH($D2*100+3,Key!$G$2:$G$263,0)),"#"),1,0)) | AU2: =IF(OR($D2="",P2="",4>$F2),0,IF(UPPER(TRIM(P2))=IFERROR(INDEX(Key!$C$2:$C$263,MATCH($D2*100+4,Key!$G$2:$G$263,0)),"#"),1,0)) | AV2: =IF(OR($D2="",Q2="",5>$F2),0,IF(UPPER(TRIM(Q2))=IFERROR(INDEX(Key!$C$2:$C$263,MATCH($D2*100+5,Key!$G$2:$G$263,0)),"#"),1,0)) | AW2: =IF(OR($D2="",R2="",6>$F2),0,IF(UPPER(TRIM(R2))=IFERROR(INDEX(Key!$C$2:$C$263,MATCH($D2*100+6,Key!$G$2:$G$263,0)),"#"),1,0)) | AX2: =IF(OR($D2="",S2="",7>$F2),0,IF(UPPER(TRIM(S2))=IFERROR(INDEX(Key!$C$2:$C$263,MATCH($D2*100+7,Key!$G$2:$G$263,0)),"#"),1,0)) | AY2: =IF(OR($D2="",T2="",8>$F2),0,IF(UPPER(TRIM(T2))=IFERROR(INDEX(Key!$C$2:$C$263,MATCH($D2*100+8,Key!$G$2:$G$263,0)),"#"),1,0)) | AZ2: =IF(OR($D2="",U2="",9>$F2),0,IF(UPPER(TRIM(U2))=IFERROR(INDEX(Key!$C$2:$C$263,MATCH($D2*100+9,Key!$G$2:$G$263,0)),"#"),1,0)) | BA2: =IF(OR($D2="",V2="",10>$F2),0,IF(UPPER(TRIM(V2))=IFERROR(INDEX(Key!$C$2:$C$263,MATCH($D2*100+10,Key!$G$2:$G$263,0)),"#"),1,0)) | BB2: =IF(OR($D2="",W2="",11>$F2),0,IF(UPPER(TRIM(W2))=IFERROR(INDEX(Key!$C$2:$C$263,MATCH($D2*100+11,Key!$G$2:$G$263,0)),"#"),1,0)) | BC2: =IF(OR($D2="",X2="",12>$F2),0,IF(UPPER(TRIM(X2))=IFERROR(INDEX(Key!$C$2:$C$263,MATCH($D2*100+12,Key!$G$2:$G$263,0)),"#"),1,0)) | BD2: =IF(OR($D2="",Y2="",13>$F2),0,IF(UPPER(TRIM(Y2))=IFERROR(INDEX(Key!$C$2:$C$263,MATCH($D2*100+13,Key!$G$2:$G$263,0)),"#"),1,0)) | BE2: =IF(OR($D2="",Z2="",14>$F2),0,IF(UPPER(TRIM(Z2))=IFERROR(INDEX(Key!$C$2:$C$263,MATCH($D2*100+14,Key!$G$2:$G$263,0)),"#"),1,0)) | BF2: =IF(OR($D2="",AA2="",15>$F2),0,IF(UPPER(TRIM(AA2))=IFERROR(INDEX(Key!$C$2:$C$263,MATCH($D2*100+15,Key!$G$2:$G$263,0)),"#"),1,0)) | BG2: =IF(OR($D2="",AB2="",16>$F2),0,IF(UPPER(TRIM(AB2))=IFERROR(INDEX(Key!$C$2:$C$263,MATCH($D2*100+16,Key!$G$2:$G$263,0)),"#"),1,0)) | BH2: =IF(OR($D2="",AC2="",17>$F2),0,IF(UPPER(TRIM(AC2))=IFERROR(INDEX(Key!$C$2:$C$263,MATCH($D2*100+17,Key!$G$2:$G$263,0)),"#"),1,0)) | BI2: =IF(OR($D2="",AD2="",18>$F2),0,IF(UPPER(TRIM(AD2))=IFERROR(INDEX(Key!$C$2:$C$263,MATCH($D2*100+18,Key!$G$2:$G$263,0)),"#"),1,0)) | BJ2: =IF(OR($D2="",AE2="",19>$F2),0,IF(UPPER(TRIM(AE2))=IFERROR(INDEX(Key!$C$2:$C$263,MATCH($D2*100+19,Key!$G$2:$G$263,0)),"#"),1,0)) | BK2: =IF(OR($D2="",AF2="",20>$F2),0,IF(UPPER(TRIM(AF2))=IFERROR(INDEX(Key!$C$2:$C$263,MATCH($D2*100+20,Key!$G$2:$G$263,0)),"#"),1,0)) | BL2: =IF(OR($D2="",AG2="",21>$F2),0,IF(UPPER(TRIM(AG2))=IFERROR(INDEX(Key!$C$2:$C$263,MATCH($D2*100+21,Key!$G$2:$G$263,0)),"#"),1,0)) | BM2: =IF(OR($D2="",AH2="",22>$F2),0,IF(UPPER(TRIM(AH2))=IFERROR(INDEX(Key!$C$2:$C$263,MATCH($D2*100+22,Key!$G$2:$G$263,0)),"#"),1,0)) | BN2: =IF(OR($D2="",AI2="",23>$F2),0,IF(UPPER(TRIM(AI2))=IFERROR(INDEX(Key!$C$2:$C$263,MATCH($D2*100+23,Key!$G$2:$G$263,0)),"#"),1,0)) | BO2: =IF(OR($D2="",AJ2="",24>$F2),0,IF(UPPER(TRIM(AJ2))=IFERROR(INDEX(Key!$C$2:$C$263,MATCH($D2*100+24,Key!$G$2:$G$263,0)),"#"),1,0)) | BP2: =IF(OR($D2="",AK2="",25>$F2),0,IF(UPPER(TRIM(AK2))=IFERROR(INDEX(Key!$C$2:$C$263,MATCH($D2*100+25,Key!$G$2:$G$263,0)),"#"),1,0)) | BQ2: =IF(OR($D2="",AL2="",26>$F2),0,IF(UPPER(TRIM(AL2))=IFERROR(INDEX(Key!$C$2:$C$263,MATCH($D2*100+26,Key!$G$2:$G$263,0)),"#"),1,0)) | BR2: =IF(OR($D2="",AM2="",27>$F2),0,IF(UPPER(TRIM(AM2))=IFERROR(INDEX(Key!$C$2:$C$263,MATCH($D2*100+27,Key!$G$2:$G$263,0)),"#"),1,0)) | BS2: =IF(OR($D2="",AN2="",28>$F2),0,IF(UPPER(TRIM(AN2))=IFERROR(INDEX(Key!$C$2:$C$263,MATCH($D2*100+28,Key!$G$2:$G$263,0)),"#"),1,0)) | BT2: =IF(OR($D2="",AO2="",29>$F2),0,IF(UPPER(TRIM(AO2))=IFERROR(INDEX(Key!$C$2:$C$263,MATCH($D2*100+29,Key!$G$2:$G$263,0)),"#"),1,0)) | BU2: =IF(OR($D2="",AP2="",30>$F2),0,IF(UPPER(TRIM(AP2))=IFERROR(INDEX(Key!$C$2:$C$263,MATCH($D2*100+30,Key!$G$2:$G$263,0)),"#"),1,0))
E3: =IF($D3="","",IFERROR(INDEX(Papers!$B$2:$B$12,MATCH($D3,Papers!$A$2:$A$12,0)),"?")) | F3: =IF($D3="","",IFERROR(INDEX(Papers!$C$2:$C$12,MATCH($D3,Papers!$A$2:$A$12,0)),0)) | G3: =IF($D3="","",COUNTIF(M3:AP3,"?*")) | H3: =IF($D3="","",SUM(AR3:BU3)) | I3: =IF($D3="","",G3-H3) | J3: =IF($D3="","",F3-G3) | K3: =IF($D3="","",H3) | L3: =IF($D3="","",IF(F3=0,"",ROUND(H3/F3*100,1))) | AR3: =IF(OR($D3="",M3="",1>$F3),0,IF(UPPER(TRIM(M3))=IFERROR(INDEX(Key!$C$2:$C$263,MATCH($D3*100+1,Key!$G$2:$G$263,0)),"#"),1,0)) | AS3: =IF(OR($D3="",N3="",2>$F3),0,IF(UPPER(TRIM(N3))=IFERROR(INDEX(Key!$C$2:$C$263,MATCH($D3*100+2,Key!$G$2:$G$263,0)),"#"),1,0)) | AT3: =IF(OR($D3="",O3="",3>$F3),0,IF(UPPER(TRIM(O3))=IFERROR(INDEX(Key!$C$2:$C$263,MATCH($D3*100+3,Key!$G$2:$G$263,0)),"#"),1,0)) | AU3: =IF(OR($D3="",P3="",4>$F3),0,IF(UPPER(TRIM(P3))=IFERROR(INDEX(Key!$C$2:$C$263,MATCH($D3*100+4,Key!$G$2:$G$263,0)),"#"),1,0)) | AV3: =IF(OR($D3="",Q3="",5>$F3),0,IF(UPPER(TRIM(Q3))=IFERROR(INDEX(Key!$C$2:$C$263,MATCH($D3*100+5,Key!$G$2:$G$263,0)),"#"),1,0)) | AW3: =IF(OR($D3="",R3="",6>$F3),0,IF(UPPER(TRIM(R3))=IFERROR(INDEX(Key!$C$2:$C$263,MATCH($D3*100+6,Key!$G$2:$G$263,0)),"#"),1,0)) | AX3: =IF(OR($D3="",S3="",7>$F3),0,IF(UPPER(TRIM(S3))=IFERROR(INDEX(Key!$C$2:$C$263,MATCH($D3*100+7,Key!$G$2:$G$263,0)),"#"),1,0)) | AY3: =IF(OR($D3="",T3="",8>$F3),0,IF(UPPER(TRIM(T3))=IFERROR(INDEX(Key!$C$2:$C$263,MATCH($D3*100+8,Key!$G$2:$G$263,0)),"#"),1,0)) | AZ3: =IF(OR($D3="",U3="",9>$F3),0,IF(UPPER(TRIM(U3))=IFERROR(INDEX(Key!$C$2:$C$263,MATCH($D3*100+9,Key!$G$2:$G$263,0)),"#"),1,0)) | BA3: =IF(OR($D3="",V3="",10>$F3),0,IF(UPPER(TRIM(V3))=IFERROR(INDEX(Key!$C$2:$C$263,MATCH($D3*100+10,Key!$G$2:$G$263,0)),"#"),1,0)) | BB3: =IF(OR($D3="",W3="",11>$F3),0,IF(UPPER(TRIM(W3))=IFERROR(INDEX(Key!$C$2:$C$263,MATCH($D3*100+11,Key!$G$2:$G$263,0)),"#"),1,0)) | BC3: =IF(OR($D3="",X3="",12>$F3),0,IF(UPPER(TRIM(X3))=IFERROR(INDEX(Key!$C$2:$C$263,MATCH($D3*100+12,Key!$G$2:$G$263,0)),"#"),1,0)) | BD3: =IF(OR($D3="",Y3="",13>$F3),0,IF(UPPER(TRIM(Y3))=IFERROR(INDEX(Key!$C$2:$C$263,MATCH($D3*100+13,Key!$G$2:$G$263,0)),"#"),1,0)) | BE3: =IF(OR($D3="",Z3="",14>$F3),0,IF(UPPER(TRIM(Z3))=IFERROR(INDEX(Key!$C$2:$C$263,MATCH($D3*100+14,Key!$G$2:$G$263,0)),"#"),1,0)) | BF3: =IF(OR($D3="",AA3="",15>$F3),0,IF(UPPER(TRIM(AA3))=IFERROR(INDEX(Key!$C$2:$C$263,MATCH($D3*100+15,Key!$G$2:$G$263,0)),"#"),1,0)) | BG3: =IF(OR($D3="",AB3="",16>$F3),0,IF(UPPER(TRIM(AB3))=IFERROR(INDEX(Key!$C$2:$C$263,MATCH($D3*100+16,Key!$G$2:$G$263,0)),"#"),1,0)) | BH3: =IF(OR($D3="",AC3="",17>$F3),0,IF(UPPER(TRIM(AC3))=IFERROR(INDEX(Key!$C$2:$C$263,MATCH($D3*100+17,Key!$G$2:$G$263,0)),"#"),1,0)) | BI3: =IF(OR($D3="",AD3="",18>$F3),0,IF(UPPER(TRIM(AD3))=IFERROR(INDEX(Key!$C$2:$C$263,MATCH($D3*100+18,Key!$G$2:$G$263,0)),"#"),1,0)) | BJ3: =IF(OR($D3="",AE3="",19>$F3),0,IF(UPPER(TRIM(AE3))=IFERROR(INDEX(Key!$C$2:$C$263,MATCH($D3*100+19,Key!$G$2:$G$263,0)),"#"),1,0)) | BK3: =IF(OR($D3="",AF3="",20>$F3),0,IF(UPPER(TRIM(AF3))=IFERROR(INDEX(Key!$C$2:$C$263,MATCH($D3*100+20,Key!$G$2:$G$263,0)),"#"),1,0)) | BL3: =IF(OR($D3="",AG3="",21>$F3),0,IF(UPPER(TRIM(AG3))=IFERROR(INDEX(Key!$C$2:$C$263,MATCH($D3*100+21,Key!$G$2:$G$263,0)),"#"),1,0)) | BM3: =IF(OR($D3="",AH3="",22>$F3),0,IF(UPPER(TRIM(AH3))=IFERROR(INDEX(Key!$C$2:$C$263,MATCH($D3*100+22,Key!$G$2:$G$263,0)),"#"),1,0)) | BN3: =IF(OR($D3="",AI3="",23>$F3),0,IF(UPPER(TRIM(AI3))=IFERROR(INDEX(Key!$C$2:$C$263,MATCH($D3*100+23,Key!$G$2:$G$263,0)),"#"),1,0)) | BO3: =IF(OR($D3="",AJ3="",24>$F3),0,IF(UPPER(TRIM(AJ3))=IFERROR(INDEX(Key!$C$2:$C$263,MATCH($D3*100+24,Key!$G$2:$G$263,0)),"#"),1,0)) | BP3: =IF(OR($D3="",AK3="",25>$F3),0,IF(UPPER(TRIM(AK3))=IFERROR(INDEX(Key!$C$2:$C$263,MATCH($D3*100+25,Key!$G$2:$G$263,0)),"#"),1,0)) | BQ3: =IF(OR($D3="",AL3="",26>$F3),0,IF(UPPER(TRIM(AL3))=IFERROR(INDEX(Key!$C$2:$C$263,MATCH($D3*100+26,Key!$G$2:$G$263,0)),"#"),1,0)) | BR3: =IF(OR($D3="",AM3="",27>$F3),0,IF(UPPER(TRIM(AM3))=IFERROR(INDEX(Key!$C$2:$C$263,MATCH($D3*100+27,Key!$G$2:$G$263,0)),"#"),1,0)) | BS3: =IF(OR($D3="",AN3="",28>$F3),0,IF(UPPER(TRIM(AN3))=IFERROR(INDEX(Key!$C$2:$C$263,MATCH($D3*100+28,Key!$G$2:$G$263,0)),"#"),1,0)) | BT3: =IF(OR($D3="",AO3="",29>$F3),0,IF(UPPER(TRIM(AO3))=IFERROR(INDEX(Key!$C$2:$C$263,MATCH($D3*100+29,Key!$G$2:$G$263,0)),"#"),1,0)) | BU3: =IF(OR($D3="",AP3="",30>$F3),0,IF(UPPER(TRIM(AP3))=IFERROR(INDEX(Key!$C$2:$C$263,MATCH($D3*100+30,Key!$G$2:$G$263,0)),"#"),1,0))
E4: =IF($D4="","",IFERROR(INDEX(Papers!$B$2:$B$12,MATCH($D4,Papers!$A$2:$A$12,0)),"?")) | F4: =IF($D4="","",IFERROR(INDEX(Papers!$C$2:$C$12,MATCH($D4,Papers!$A$2:$A$12,0)),0)) | G4: =IF($D4="","",COUNTIF(M4:AP4,"?*")) | H4: =IF($D4="","",SUM(AR4:BU4)) | I4: =IF($D4="","",G4-H4) | J4: =IF($D4="","",F4-G4) | K4: =IF($D4="","",H4) | L4: =IF($D4="","",IF(F4=0,"",ROUND(H4/F4*100,1))) | AR4: =IF(OR($D4="",M4="",1>$F4),0,IF(UPPER(TRIM(M4))=IFERROR(INDEX(Key!$C$2:$C$263,MATCH($D4*100+1,Key!$G$2:$G$263,0)),"#"),1,0)) | AS4: =IF(OR($D4="",N4="",2>$F4),0,IF(UPPER(TRIM(N4))=IFERROR(INDEX(Key!$C$2:$C$263,MATCH($D4*100+2,Key!$G$2:$G$263,0)),"#"),1,0)) | AT4: =IF(OR($D4="",O4="",3>$F4),0,IF(UPPER(TRIM(O4))=IFERROR(INDEX(Key!$C$2:$C$263,MATCH($D4*100+3,Key!$G$2:$G$263,0)),"#"),1,0)) | AU4: =IF(OR($D4="",P4="",4>$F4),0,IF(UPPER(TRIM(P4))=IFERROR(INDEX(Key!$C$2:$C$263,MATCH($D4*100+4,Key!$G$2:$G$263,0)),"#"),1,0)) | AV4: =IF(OR($D4="",Q4="",5>$F4),0,IF(UPPER(TRIM(Q4))=IFERROR(INDEX(Key!$C$2:$C$263,MATCH($D4*100+5,Key!$G$2:$G$263,0)),"#"),1,0)) | AW4: =IF(OR($D4="",R4="",6>$F4),0,IF(UPPER(TRIM(R4))=IFERROR(INDEX(Key!$C$2:$C$263,MATCH($D4*100+6,Key!$G$2:$G$263,0)),"#"),1,0)) | AX4: =IF(OR($D4="",S4="",7>$F4),0,IF(UPPER(TRIM(S4))=IFERROR(INDEX(Key!$C$2:$C$263,MATCH($D4*100+7,Key!$G$2:$G$263,0)),"#"),1,0)) | AY4: =IF(OR($D4="",T4="",8>$F4),0,IF(UPPER(TRIM(T4))=IFERROR(INDEX(Key!$C$2:$C$263,MATCH($D4*100+8,Key!$G$2:$G$263,0)),"#"),1,0)) | AZ4: =IF(OR($D4="",U4="",9>$F4),0,IF(UPPER(TRIM(U4))=IFERROR(INDEX(Key!$C$2:$C$263,MATCH($D4*100+9,Key!$G$2:$G$263,0)),"#"),1,0)) | BA4: =IF(OR($D4="",V4="",10>$F4),0,IF(UPPER(TRIM(V4))=IFERROR(INDEX(Key!$C$2:$C$263,MATCH($D4*100+10,Key!$G$2:$G$263,0)),"#"),1,0)) | BB4: =IF(OR($D4="",W4="",11>$F4),0,IF(UPPER(TRIM(W4))=IFERROR(INDEX(Key!$C$2:$C$263,MATCH($D4*100+11,Key!$G$2:$G$263,0)),"#"),1,0)) | BC4: =IF(OR($D4="",X4="",12>$F4),0,IF(UPPER(TRIM(X4))=IFERROR(INDEX(Key!$C$2:$C$263,MATCH($D4*100+12,Key!$G$2:$G$263,0)),"#"),1,0)) | BD4: =IF(OR($D4="",Y4="",13>$F4),0,IF(UPPER(TRIM(Y4))=IFERROR(INDEX(Key!$C$2:$C$263,MATCH($D4*100+13,Key!$G$2:$G$263,0)),"#"),1,0)) | BE4: =IF(OR($D4="",Z4="",14>$F4),0,IF(UPPER(TRIM(Z4))=IFERROR(INDEX(Key!$C$2:$C$263,MATCH($D4*100+14,Key!$G$2:$G$263,0)),"#"),1,0)) | BF4: =IF(OR($D4="",AA4="",15>$F4),0,IF(UPPER(TRIM(AA4))=IFERROR(INDEX(Key!$C$2:$C$263,MATCH($D4*100+15,Key!$G$2:$G$263,0)),"#"),1,0)) | BG4: =IF(OR($D4="",AB4="",16>$F4),0,IF(UPPER(TRIM(AB4))=IFERROR(INDEX(Key!$C$2:$C$263,MATCH($D4*100+16,Key!$G$2:$G$263,0)),"#"),1,0)) | BH4: =IF(OR($D4="",AC4="",17>$F4),0,IF(UPPER(TRIM(AC4))=IFERROR(INDEX(Key!$C$2:$C$263,MATCH($D4*100+17,Key!$G$2:$G$263,0)),"#"),1,0)) | BI4: =IF(OR($D4="",AD4="",18>$F4),0,IF(UPPER(TRIM(AD4))=IFERROR(INDEX(Key!$C$2:$C$263,MATCH($D4*100+18,Key!$G$2:$G$263,0)),"#"),1,0)) | BJ4: =IF(OR($D4="",AE4="",19>$F4),0,IF(UPPER(TRIM(AE4))=IFERROR(INDEX(Key!$C$2:$C$263,MATCH($D4*100+19,Key!$G$2:$G$263,0)),"#"),1,0)) | BK4: =IF(OR($D4="",AF4="",20>$F4),0,IF(UPPER(TRIM(AF4))=IFERROR(INDEX(Key!$C$2:$C$263,MATCH($D4*100+20,Key!$G$2:$G$263,0)),"#"),1,0)) | BL4: =IF(OR($D4="",AG4="",21>$F4),0,IF(UPPER(TRIM(AG4))=IFERROR(INDEX(Key!$C$2:$C$263,MATCH($D4*100+21,Key!$G$2:$G$263,0)),"#"),1,0)) | BM4: =IF(OR($D4="",AH4="",22>$F4),0,IF(UPPER(TRIM(AH4))=IFERROR(INDEX(Key!$C$2:$C$263,MATCH($D4*100+22,Key!$G$2:$G$263,0)),"#"),1,0)) | BN4: =IF(OR($D4="",AI4="",23>$F4),0,IF(UPPER(TRIM(AI4))=IFERROR(INDEX(Key!$C$2:$C$263,MATCH($D4*100+23,Key!$G$2:$G$263,0)),"#"),1,0)) | BO4: =IF(OR($D4="",AJ4="",24>$F4),0,IF(UPPER(TRIM(AJ4))=IFERROR(INDEX(Key!$C$2:$C$263,MATCH($D4*100+24,Key!$G$2:$G$263,0)),"#"),1,0)) | BP4: =IF(OR($D4="",AK4="",25>$F4),0,IF(UPPER(TRIM(AK4))=IFERROR(INDEX(Key!$C$2:$C$263,MATCH($D4*100+25,Key!$G$2:$G$263,0)),"#"),1,0)) | BQ4: =IF(OR($D4="",AL4="",26>$F4),0,IF(UPPER(TRIM(AL4))=IFERROR(INDEX(Key!$C$2:$C$263,MATCH($D4*100+26,Key!$G$2:$G$263,0)),"#"),1,0)) | BR4: =IF(OR($D4="",AM4="",27>$F4),0,IF(UPPER(TRIM(AM4))=IFERROR(INDEX(Key!$C$2:$C$263,MATCH($D4*100+27,Key!$G$2:$G$263,0)),"#"),1,0)) | BS4: =IF(OR($D4="",AN4="",28>$F4),0,IF(UPPER(TRIM(AN4))=IFERROR(INDEX(Key!$C$2:$C$263,MATCH($D4*100+28,Key!$G$2:$G$263,0)),"#"),1,0)) | BT4: =IF(OR($D4="",AO4="",29>$F4),0,IF(UPPER(TRIM(AO4))=IFERROR(INDEX(Key!$C$2:$C$263,MATCH($D4*100+29,Key!$G$2:$G$263,0)),"#"),1,0)) | BU4: =IF(OR($D4="",AP4="",30>$F4),0,IF(UPPER(TRIM(AP4))=IFERROR(INDEX(Key!$C$2:$C$263,MATCH($D4*100+30,Key!$G$2:$G$263,0)),"#"),1,0))
E5: =IF($D5="","",IFERROR(INDEX(Papers!$B$2:$B$12,MATCH($D5,Papers!$A$2:$A$12,0)),"?")) | F5: =IF($D5="","",IFERROR(INDEX(Papers!$C$2:$C$12,MATCH($D5,Papers!$A$2:$A$12,0)),0)) | G5: =IF($D5="","",COUNTIF(M5:AP5,"?*")) | H5: =IF($D5="","",SUM(AR5:BU5)) | I5: =IF($D5="","",G5-H5) | J5: =IF($D5="","",F5-G5) | K5: =IF($D5="","",H5) | L5: =IF($D5="","",IF(F5=0,"",ROUND(H5/F5*100,1))) | AR5: =IF(OR($D5="",M5="",1>$F5),0,IF(UPPER(TRIM(M5))=IFERROR(INDEX(Key!$C$2:$C$263,MATCH($D5*100+1,Key!$G$2:$G$263,0)),"#"),1,0)) | AS5: =IF(OR($D5="",N5="",2>$F5),0,IF(UPPER(TRIM(N5))=IFERROR(INDEX(Key!$C$2:$C$263,MATCH($D5*100+2,Key!$G$2:$G$263,0)),"#"),1,0)) | AT5: =IF(OR($D5="",O5="",3>$F5),0,IF(UPPER(TRIM(O5))=IFERROR(INDEX(Key!$C$2:$C$263,MATCH($D5*100+3,Key!$G$2:$G$263,0)),"#"),1,0)) | AU5: =IF(OR($D5="",P5="",4>$F5),0,IF(UPPER(TRIM(P5))=IFERROR(INDEX(Key!$C$2:$C$263,MATCH($D5*100+4,Key!$G$2:$G$263,0)),"#"),1,0)) | AV5: =IF(OR($D5="",Q5="",5>$F5),0,IF(UPPER(TRIM(Q5))=IFERROR(INDEX(Key!$C$2:$C$263,MATCH($D5*100+5,Key!$G$2:$G$263,0)),"#"),1,0)) | AW5: =IF(OR($D5="",R5="",6>$F5),0,IF(UPPER(TRIM(R5))=IFERROR(INDEX(Key!$C$2:$C$263,MATCH($D5*100+6,Key!$G$2:$G$263,0)),"#"),1,0)) | AX5: =IF(OR($D5="",S5="",7>$F5),0,IF(UPPER(TRIM(S5))=IFERROR(INDEX(Key!$C$2:$C$263,MATCH($D5*100+7,Key!$G$2:$G$263,0)),"#"),1,0)) | AY5: =IF(OR($D5="",T5="",8>$F5),0,IF(UPPER(TRIM(T5))=IFERROR(INDEX(Key!$C$2:$C$263,MATCH($D5*100+8,Key!$G$2:$G$263,0)),"#"),1,0)) | AZ5: =IF(OR($D5="",U5="",9>$F5),0,IF(UPPER(TRIM(U5))=IFERROR(INDEX(Key!$C$2:$C$263,MATCH($D5*100+9,Key!$G$2:$G$263,0)),"#"),1,0)) | BA5: =IF(OR($D5="",V5="",10>$F5),0,IF(UPPER(TRIM(V5))=IFERROR(INDEX(Key!$C$2:$C$263,MATCH($D5*100+10,Key!$G$2:$G$263,0)),"#"),1,0)) | BB5: =IF(OR($D5="",W5="",11>$F5),0,IF(UPPER(TRIM(W5))=IFERROR(INDEX(Key!$C$2:$C$263,MATCH($D5*100+11,Key!$G$2:$G$263,0)),"#"),1,0)) | BC5: =IF(OR($D5="",X5="",12>$F5),0,IF(UPPER(TRIM(X5))=IFERROR(INDEX(Key!$C$2:$C$263,MATCH($D5*100+12,Key!$G$2:$G$263,0)),"#"),1,0)) | BD5: =IF(OR($D5="",Y5="",13>$F5),0,IF(UPPER(TRIM(Y5))=IFERROR(INDEX(Key!$C$2:$C$263,MATCH($D5*100+13,Key!$G$2:$G$263,0)),"#"),1,0)) | BE5: =IF(OR($D5="",Z5="",14>$F5),0,IF(UPPER(TRIM(Z5))=IFERROR(INDEX(Key!$C$2:$C$263,MATCH($D5*100+14,Key!$G$2:$G$263,0)),"#"),1,0)) | BF5: =IF(OR($D5="",AA5="",15>$F5),0,IF(UPPER(TRIM(AA5))=IFERROR(INDEX(Key!$C$2:$C$263,MATCH($D5*100+15,Key!$G$2:$G$263,0)),"#"),1,0)) | BG5: =IF(OR($D5="",AB5="",16>$F5),0,IF(UPPER(TRIM(AB5))=IFERROR(INDEX(Key!$C$2:$C$263,MATCH($D5*100+16,Key!$G$2:$G$263,0)),"#"),1,0)) | BH5: =IF(OR($D5="",AC5="",17>$F5),0,IF(UPPER(TRIM(AC5))=IFERROR(INDEX(Key!$C$2:$C$263,MATCH($D5*100+17,Key!$G$2:$G$263,0)),"#"),1,0)) | BI5: =IF(OR($D5="",AD5="",18>$F5),0,IF(UPPER(TRIM(AD5))=IFERROR(INDEX(Key!$C$2:$C$263,MATCH($D5*100+18,Key!$G$2:$G$263,0)),"#"),1,0)) | BJ5: =IF(OR($D5="",AE5="",19>$F5),0,IF(UPPER(TRIM(AE5))=IFERROR(INDEX(Key!$C$2:$C$263,MATCH($D5*100+19,Key!$G$2:$G$263,0)),"#"),1,0)) | BK5: =IF(OR($D5="",AF5="",20>$F5),0,IF(UPPER(TRIM(AF5))=IFERROR(INDEX(Key!$C$2:$C$263,MATCH($D5*100+20,Key!$G$2:$G$263,0)),"#"),1,0)) | BL5: =IF(OR($D5="",AG5="",21>$F5),0,IF(UPPER(TRIM(AG5))=IFERROR(INDEX(Key!$C$2:$C$263,MATCH($D5*100+21,Key!$G$2:$G$263,0)),"#"),1,0)) | BM5: =IF(OR($D5="",AH5="",22>$F5),0,IF(UPPER(TRIM(AH5))=IFERROR(INDEX(Key!$C$2:$C$263,MATCH($D5*100+22,Key!$G$2:$G$263,0)),"#"),1,0)) | BN5: =IF(OR($D5="",AI5="",23>$F5),0,IF(UPPER(TRIM(AI5))=IFERROR(INDEX(Key!$C$2:$C$263,MATCH($D5*100+23,Key!$G$2:$G$263,0)),"#"),1,0)) | BO5: =IF(OR($D5="",AJ5="",24>$F5),0,IF(UPPER(TRIM(AJ5))=IFERROR(INDEX(Key!$C$2:$C$263,MATCH($D5*100+24,Key!$G$2:$G$263,0)),"#"),1,0)) | BP5: =IF(OR($D5="",AK5="",25>$F5),0,IF(UPPER(TRIM(AK5))=IFERROR(INDEX(Key!$C$2:$C$263,MATCH($D5*100+25,Key!$G$2:$G$263,0)),"#"),1,0)) | BQ5: =IF(OR($D5="",AL5="",26>$F5),0,IF(UPPER(TRIM(AL5))=IFERROR(INDEX(Key!$C$2:$C$263,MATCH($D5*100+26,Key!$G$2:$G$263,0)),"#"),1,0)) | BR5: =IF(OR($D5="",AM5="",27>$F5),0,IF(UPPER(TRIM(AM5))=IFERROR(INDEX(Key!$C$2:$C$263,MATCH($D5*100+27,Key!$G$2:$G$263,0)),"#"),1,0)) | BS5: =IF(OR($D5="",AN5="",28>$F5),0,IF(UPPER(TRIM(AN5))=IFERROR(INDEX(Key!$C$2:$C$263,MATCH($D5*100+28,Key!$G$2:$G$263,0)),"#"),1,0)) | BT5: =IF(OR($D5="",AO5="",29>$F5),0,IF(UPPER(TRIM(AO5))=IFERROR(INDEX(Key!$C$2:$C$263,MATCH($D5*100+29,Key!$G$2:$G$263,0)),"#"),1,0)) | BU5: =IF(OR($D5="",AP5="",30>$F5),0,IF(UPPER(TRIM(AP5))=IFERROR(INDEX(Key!$C$2:$C$263,MATCH($D5*100+30,Key!$G$2:$G$263,0)),"#"),1,0))
E6: =IF($D6="","",IFERROR(INDEX(Papers!$B$2:$B$12,MATCH($D6,Papers!$A$2:$A$12,0)),"?")) | F6: =IF($D6="","",IFERROR(INDEX(Papers!$C$2:$C$12,MATCH($D6,Papers!$A$2:$A$12,0)),0)) | G6: =IF($D6="","",COUNTIF(M6:AP6,"?*")) | H6: =IF($D6="","",SUM(AR6:BU6)) | I6: =IF($D6="","",G6-H6) | J6: =IF($D6="","",F6-G6) | K6: =IF($D6="","",H6) | L6: =IF($D6="","",IF(F6=0,"",ROUND(H6/F6*100,1))) | AR6: =IF(OR($D6="",M6="",1>$F6),0,IF(UPPER(TRIM(M6))=IFERROR(INDEX(Key!$C$2:$C$263,MATCH($D6*100+1,Key!$G$2:$G$263,0)),"#"),1,0)) | AS6: =IF(OR($D6="",N6="",2>$F6),0,IF(UPPER(TRIM(N6))=IFERROR(INDEX(Key!$C$2:$C$263,MATCH($D6*100+2,Key!$G$2:$G$263,0)),"#"),1,0)) | AT6: =IF(OR($D6="",O6="",3>$F6),0,IF(UPPER(TRIM(O6))=IFERROR(INDEX(Key!$C$2:$C$263,MATCH($D6*100+3,Key!$G$2:$G$263,0)),"#"),1,0)) | AU6: =IF(OR($D6="",P6="",4>$F6),0,IF(UPPER(TRIM(P6))=IFERROR(INDEX(Key!$C$2:$C$263,MATCH($D6*100+4,Key!$G$2:$G$263,0)),"#"),1,0)) | AV6: =IF(OR($D6="",Q6="",5>$F6),0,IF(UPPER(TRIM(Q6))=IFERROR(INDEX(Key!$C$2:$C$263,MATCH($D6*100+5,Key!$G$2:$G$263,0)),"#"),1,0)) | AW6: =IF(OR($D6="",R6="",6>$F6),0,IF(UPPER(TRIM(R6))=IFERROR(INDEX(Key!$C$2:$C$263,MATCH($D6*100+6,Key!$G$2:$G$263,0)),"#"),1,0)) | AX6: =IF(OR($D6="",S6="",7>$F6),0,IF(UPPER(TRIM(S6))=IFERROR(INDEX(Key!$C$2:$C$263,MATCH($D6*100+7,Key!$G$2:$G$263,0)),"#"),1,0)) | AY6: =IF(OR($D6="",T6="",8>$F6),0,IF(UPPER(TRIM(T6))=IFERROR(INDEX(Key!$C$2:$C$263,MATCH($D6*100+8,Key!$G$2:$G$263,0)),"#"),1,0)) | AZ6: =IF(OR($D6="",U6="",9>$F6),0,IF(UPPER(TRIM(U6))=IFERROR(INDEX(Key!$C$2:$C$263,MATCH($D6*100+9,Key!$G$2:$G$263,0)),"#"),1,0)) | BA6: =IF(OR($D6="",V6="",10>$F6),0,IF(UPPER(TRIM(V6))=IFERROR(INDEX(Key!$C$2:$C$263,MATCH($D6*100+10,Key!$G$2:$G$263,0)),"#"),1,0)) | BB6: =IF(OR($D6="",W6="",11>$F6),0,IF(UPPER(TRIM(W6))=IFERROR(INDEX(Key!$C$2:$C$263,MATCH($D6*100+11,Key!$G$2:$G$263,0)),"#"),1,0)) | BC6: =IF(OR($D6="",X6="",12>$F6),0,IF(UPPER(TRIM(X6))=IFERROR(INDEX(Key!$C$2:$C$263,MATCH($D6*100+12,Key!$G$2:$G$263,0)),"#"),1,0)) | BD6: =IF(OR($D6="",Y6="",13>$F6),0,IF(UPPER(TRIM(Y6))=IFERROR(INDEX(Key!$C$2:$C$263,MATCH($D6*100+13,Key!$G$2:$G$263,0)),"#"),1,0)) | BE6: =IF(OR($D6="",Z6="",14>$F6),0,IF(UPPER(TRIM(Z6))=IFERROR(INDEX(Key!$C$2:$C$263,MATCH($D6*100+14,Key!$G$2:$G$263,0)),"#"),1,0)) | BF6: =IF(OR($D6="",AA6="",15>$F6),0,IF(UPPER(TRIM(AA6))=IFERROR(INDEX(Key!$C$2:$C$263,MATCH($D6*100+15,Key!$G$2:$G$263,0)),"#"),1,0)) | BG6: =IF(OR($D6="",AB6="",16>$F6),0,IF(UPPER(TRIM(AB6))=IFERROR(INDEX(Key!$C$2:$C$263,MATCH($D6*100+16,Key!$G$2:$G$263,0)),"#"),1,0)) | BH6: =IF(OR($D6="",AC6="",17>$F6),0,IF(UPPER(TRIM(AC6))=IFERROR(INDEX(Key!$C$2:$C$263,MATCH($D6*100+17,Key!$G$2:$G$263,0)),"#"),1,0)) | BI6: =IF(OR($D6="",AD6="",18>$F6),0,IF(UPPER(TRIM(AD6))=IFERROR(INDEX(Key!$C$2:$C$263,MATCH($D6*100+18,Key!$G$2:$G$263,0)),"#"),1,0)) | BJ6: =IF(OR($D6="",AE6="",19>$F6),0,IF(UPPER(TRIM(AE6))=IFERROR(INDEX(Key!$C$2:$C$263,MATCH($D6*100+19,Key!$G$2:$G$263,0)),"#"),1,0)) | BK6: =IF(OR($D6="",AF6="",20>$F6),0,IF(UPPER(TRIM(AF6))=IFERROR(INDEX(Key!$C$2:$C$263,MATCH($D6*100+20,Key!$G$2:$G$263,0)),"#"),1,0)) | BL6: =IF(OR($D6="",AG6="",21>$F6),0,IF(UPPER(TRIM(AG6))=IFERROR(INDEX(Key!$C$2:$C$263,MATCH($D6*100+21,Key!$G$2:$G$263,0)),"#"),1,0)) | BM6: =IF(OR($D6="",AH6="",22>$F6),0,IF(UPPER(TRIM(AH6))=IFERROR(INDEX(Key!$C$2:$C$263,MATCH($D6*100+22,Key!$G$2:$G$263,0)),"#"),1,0)) | BN6: =IF(OR($D6="",AI6="",23>$F6),0,IF(UPPER(TRIM(AI6))=IFERROR(INDEX(Key!$C$2:$C$263,MATCH($D6*100+23,Key!$G$2:$G$263,0)),"#"),1,0)) | BO6: =IF(OR($D6="",AJ6="",24>$F6),0,IF(UPPER(TRIM(AJ6))=IFERROR(INDEX(Key!$C$2:$C$263,MATCH($D6*100+24,Key!$G$2:$G$263,0)),"#"),1,0)) | BP6: =IF(OR($D6="",AK6="",25>$F6),0,IF(UPPER(TRIM(AK6))=IFERROR(INDEX(Key!$C$2:$C$263,MATCH($D6*100+25,Key!$G$2:$G$263,0)),"#"),1,0)) | BQ6: =IF(OR($D6="",AL6="",26>$F6),0,IF(UPPER(TRIM(AL6))=IFERROR(INDEX(Key!$C$2:$C$263,MATCH($D6*100+26,Key!$G$2:$G$263,0)),"#"),1,0)) | BR6: =IF(OR($D6="",AM6="",27>$F6),0,IF(UPPER(TRIM(AM6))=IFERROR(INDEX(Key!$C$2:$C$263,MATCH($D6*100+27,Key!$G$2:$G$263,0)),"#"),1,0)) | BS6: =IF(OR($D6="",AN6="",28>$F6),0,IF(UPPER(TRIM(AN6))=IFERROR(INDEX(Key!$C$2:$C$263,MATCH($D6*100+28,Key!$G$2:$G$263,0)),"#"),1,0)) | BT6: =IF(OR($D6="",AO6="",29>$F6),0,IF(UPPER(TRIM(AO6))=IFERROR(INDEX(Key!$C$2:$C$263,MATCH($D6*100+29,Key!$G$2:$G$263,0)),"#"),1,0)) | BU6: =IF(OR($D6="",AP6="",30>$F6),0,IF(UPPER(TRIM(AP6))=IFERROR(INDEX(Key!$C$2:$C$263,MATCH($D6*100+30,Key!$G$2:$G$263,0)),"#"),1,0))
E7: =IF($D7="","",IFERROR(INDEX(Papers!$B$2:$B$12,MATCH($D7,Papers!$A$2:$A$12,0)),"?")) | F7: =IF($D7="","",IFERROR(INDEX(Papers!$C$2:$C$12,MATCH($D7,Papers!$A$2:$A$12,0)),0)) | G7: =IF($D7="","",COUNTIF(M7:AP7,"?*")) | H7: =IF($D7="","",SUM(AR7:BU7)) | I7: =IF($D7="","",G7-H7) | J7: =IF($D7="","",F7-G7) | K7: =IF($D7="","",H7) | L7: =IF($D7="","",IF(F7=0,"",ROUND(H7/F7*100,1))) | AR7: =IF(OR($D7="",M7="",1>$F7),0,IF(UPPER(TRIM(M7))=IFERROR(INDEX(Key!$C$2:$C$263,MATCH($D7*100+1,Key!$G$2:$G$263,0)),"#"),1,0)) | AS7: =IF(OR($D7="",N7="",2>$F7),0,IF(UPPER(TRIM(N7))=IFERROR(INDEX(Key!$C$2:$C$263,MATCH($D7*100+2,Key!$G$2:$G$263,0)),"#"),1,0)) | AT7: =IF(OR($D7="",O7="",3>$F7),0,IF(UPPER(TRIM(O7))=IFERROR(INDEX(Key!$C$2:$C$263,MATCH($D7*100+3,Key!$G$2:$G$263,0)),"#"),1,0)) | AU7: =IF(OR($D7="",P7="",4>$F7),0,IF(UPPER(TRIM(P7))=IFERROR(INDEX(Key!$C$2:$C$263,MATCH($D7*100+4,Key!$G$2:$G$263,0)),"#"),1,0)) | AV7: =IF(OR($D7="",Q7="",5>$F7),0,IF(UPPER(TRIM(Q7))=IFERROR(INDEX(Key!$C$2:$C$263,MATCH($D7*100+5,Key!$G$2:$G$263,0)),"#"),1,0)) | AW7: =IF(OR($D7="",R7="",6>$F7),0,IF(UPPER(TRIM(R7))=IFERROR(INDEX(Key!$C$2:$C$263,MATCH($D7*100+6,Key!$G$2:$G$263,0)),"#"),1,0)) | AX7: =IF(OR($D7="",S7="",7>$F7),0,IF(UPPER(TRIM(S7))=IFERROR(INDEX(Key!$C$2:$C$263,MATCH($D7*100+7,Key!$G$2:$G$263,0)),"#"),1,0)) | AY7: =IF(OR($D7="",T7="",8>$F7),0,IF(UPPER(TRIM(T7))=IFERROR(INDEX(Key!$C$2:$C$263,MATCH($D7*100+8,Key!$G$2:$G$263,0)),"#"),1,0)) | AZ7: =IF(OR($D7="",U7="",9>$F7),0,IF(UPPER(TRIM(U7))=IFERROR(INDEX(Key!$C$2:$C$263,MATCH($D7*100+9,Key!$G$2:$G$263,0)),"#"),1,0)) | BA7: =IF(OR($D7="",V7="",10>$F7),0,IF(UPPER(TRIM(V7))=IFERROR(INDEX(Key!$C$2:$C$263,MATCH($D7*100+10,Key!$G$2:$G$263,0)),"#"),1,0)) | BB7: =IF(OR($D7="",W7="",11>$F7),0,IF(UPPER(TRIM(W7))=IFERROR(INDEX(Key!$C$2:$C$263,MATCH($D7*100+11,Key!$G$2:$G$263,0)),"#"),1,0)) | BC7: =IF(OR($D7="",X7="",12>$F7),0,IF(UPPER(TRIM(X7))=IFERROR(INDEX(Key!$C$2:$C$263,MATCH($D7*100+12,Key!$G$2:$G$263,0)),"#"),1,0)) | BD7: =IF(OR($D7="",Y7="",13>$F7),0,IF(UPPER(TRIM(Y7))=IFERROR(INDEX(Key!$C$2:$C$263,MATCH($D7*100+13,Key!$G$2:$G$263,0)),"#"),1,0)) | BE7: =IF(OR($D7="",Z7="",14>$F7),0,IF(UPPER(TRIM(Z7))=IFERROR(INDEX(Key!$C$2:$C$263,MATCH($D7*100+14,Key!$G$2:$G$263,0)),"#"),1,0)) | BF7: =IF(OR($D7="",AA7="",15>$F7),0,IF(UPPER(TRIM(AA7))=IFERROR(INDEX(Key!$C$2:$C$263,MATCH($D7*100+15,Key!$G$2:$G$263,0)),"#"),1,0)) | BG7: =IF(OR($D7="",AB7="",16>$F7),0,IF(UPPER(TRIM(AB7))=IFERROR(INDEX(Key!$C$2:$C$263,MATCH($D7*100+16,Key!$G$2:$G$263,0)),"#"),1,0)) | BH7: =IF(OR($D7="",AC7="",17>$F7),0,IF(UPPER(TRIM(AC7))=IFERROR(INDEX(Key!$C$2:$C$263,MATCH($D7*100+17,Key!$G$2:$G$263,0)),"#"),1,0)) | BI7: =IF(OR($D7="",AD7="",18>$F7),0,IF(UPPER(TRIM(AD7))=IFERROR(INDEX(Key!$C$2:$C$263,MATCH($D7*100+18,Key!$G$2:$G$263,0)),"#"),1,0)) | BJ7: =IF(OR($D7="",AE7="",19>$F7),0,IF(UPPER(TRIM(AE7))=IFERROR(INDEX(Key!$C$2:$C$263,MATCH($D7*100+19,Key!$G$2:$G$263,0)),"#"),1,0)) | BK7: =IF(OR($D7="",AF7="",20>$F7),0,IF(UPPER(TRIM(AF7))=IFERROR(INDEX(Key!$C$2:$C$263,MATCH($D7*100+20,Key!$G$2:$G$263,0)),"#"),1,0)) | BL7: =IF(OR($D7="",AG7="",21>$F7),0,IF(UPPER(TRIM(AG7))=IFERROR(INDEX(Key!$C$2:$C$263,MATCH($D7*100+21,Key!$G$2:$G$263,0)),"#"),1,0)) | BM7: =IF(OR($D7="",AH7="",22>$F7),0,IF(UPPER(TRIM(AH7))=IFERROR(INDEX(Key!$C$2:$C$263,MATCH($D7*100+22,Key!$G$2:$G$263,0)),"#"),1,0)) | BN7: =IF(OR($D7="",AI7="",23>$F7),0,IF(UPPER(TRIM(AI7))=IFERROR(INDEX(Key!$C$2:$C$263,MATCH($D7*100+23,Key!$G$2:$G$263,0)),"#"),1,0)) | BO7: =IF(OR($D7="",AJ7="",24>$F7),0,IF(UPPER(TRIM(AJ7))=IFERROR(INDEX(Key!$C$2:$C$263,MATCH($D7*100+24,Key!$G$2:$G$263,0)),"#"),1,0)) | BP7: =IF(OR($D7="",AK7="",25>$F7),0,IF(UPPER(TRIM(AK7))=IFERROR(INDEX(Key!$C$2:$C$263,MATCH($D7*100+25,Key!$G$2:$G$263,0)),"#"),1,0)) | BQ7: =IF(OR($D7="",AL7="",26>$F7),0,IF(UPPER(TRIM(AL7))=IFERROR(INDEX(Key!$C$2:$C$263,MATCH($D7*100+26,Key!$G$2:$G$263,0)),"#"),1,0)) | BR7: =IF(OR($D7="",AM7="",27>$F7),0,IF(UPPER(TRIM(AM7))=IFERROR(INDEX(Key!$C$2:$C$263,MATCH($D7*100+27,Key!$G$2:$G$263,0)),"#"),1,0)) | BS7: =IF(OR($D7="",AN7="",28>$F7),0,IF(UPPER(TRIM(AN7))=IFERROR(INDEX(Key!$C$2:$C$263,MATCH($D7*100+28,Key!$G$2:$G$263,0)),"#"),1,0)) | BT7: =IF(OR($D7="",AO7="",29>$F7),0,IF(UPPER(TRIM(AO7))=IFERROR(INDEX(Key!$C$2:$C$263,MATCH($D7*100+29,Key!$G$2:$G$263,0)),"#"),1,0)) | BU7: =IF(OR($D7="",AP7="",30>$F7),0,IF(UPPER(TRIM(AP7))=IFERROR(INDEX(Key!$C$2:$C$263,MATCH($D7*100+30,Key!$G$2:$G$263,0)),"#"),1,0))
E8: =IF($D8="","",IFERROR(INDEX(Papers!$B$2:$B$12,MATCH($D8,Papers!$A$2:$A$12,0)),"?")) | F8: =IF($D8="","",IFERROR(INDEX(Papers!$C$2:$C$12,MATCH($D8,Papers!$A$2:$A$12,0)),0)) | G8: =IF($D8="","",COUNTIF(M8:AP8,"?*")) | H8: =IF($D8="","",SUM(AR8:BU8)) | I8: =IF($D8="","",G8-H8) | J8: =IF($D8="","",F8-G8) | K8: =IF($D8="","",H8) | L8: =IF($D8="","",IF(F8=0,"",ROUND(H8/F8*100,1))) | AR8: =IF(OR($D8="",M8="",1>$F8),0,IF(UPPER(TRIM(M8))=IFERROR(INDEX(Key!$C$2:$C$263,MATCH($D8*100+1,Key!$G$2:$G$263,0)),"#"),1,0)) | AS8: =IF(OR($D8="",N8="",2>$F8),0,IF(UPPER(TRIM(N8))=IFERROR(INDEX(Key!$C$2:$C$263,MATCH($D8*100+2,Key!$G$2:$G$263,0)),"#"),1,0)) | AT8: =IF(OR($D8="",O8="",3>$F8),0,IF(UPPER(TRIM(O8))=IFERROR(INDEX(Key!$C$2:$C$263,MATCH($D8*100+3,Key!$G$2:$G$263,0)),"#"),1,0)) | AU8: =IF(OR($D8="",P8="",4>$F8),0,IF(UPPER(TRIM(P8))=IFERROR(INDEX(Key!$C$2:$C$263,MATCH($D8*100+4,Key!$G$2:$G$263,0)),"#"),1,0)) | AV8: =IF(OR($D8="",Q8="",5>$F8),0,IF(UPPER(TRIM(Q8))=IFERROR(INDEX(Key!$C$2:$C$263,MATCH($D8*100+5,Key!$G$2:$G$263,0)),"#"),1,0)) | AW8: =IF(OR($D8="",R8="",6>$F8),0,IF(UPPER(TRIM(R8))=IFERROR(INDEX(Key!$C$2:$C$263,MATCH($D8*100+6,Key!$G$2:$G$263,0)),"#"),1,0)) | AX8: =IF(OR($D8="",S8="",7>$F8),0,IF(UPPER(TRIM(S8))=IFERROR(INDEX(Key!$C$2:$C$263,MATCH($D8*100+7,Key!$G$2:$G$263,0)),"#"),1,0)) | AY8: =IF(OR($D8="",T8="",8>$F8),0,IF(UPPER(TRIM(T8))=IFERROR(INDEX(Key!$C$2:$C$263,MATCH($D8*100+8,Key!$G$2:$G$263,0)),"#"),1,0)) | AZ8: =IF(OR($D8="",U8="",9>$F8),0,IF(UPPER(TRIM(U8))=IFERROR(INDEX(Key!$C$2:$C$263,MATCH($D8*100+9,Key!$G$2:$G$263,0)),"#"),1,0)) | BA8: =IF(OR($D8="",V8="",10>$F8),0,IF(UPPER(TRIM(V8))=IFERROR(INDEX(Key!$C$2:$C$263,MATCH($D8*100+10,Key!$G$2:$G$263,0)),"#"),1,0)) | BB8: =IF(OR($D8="",W8="",11>$F8),0,IF(UPPER(TRIM(W8))=IFERROR(INDEX(Key!$C$2:$C$263,MATCH($D8*100+11,Key!$G$2:$G$263,0)),"#"),1,0)) | BC8: =IF(OR($D8="",X8="",12>$F8),0,IF(UPPER(TRIM(X8))=IFERROR(INDEX(Key!$C$2:$C$263,MATCH($D8*100+12,Key!$G$2:$G$263,0)),"#"),1,0)) | BD8: =IF(OR($D8="",Y8="",13>$F8),0,IF(UPPER(TRIM(Y8))=IFERROR(INDEX(Key!$C$2:$C$263,MATCH($D8*100+13,Key!$G$2:$G$263,0)),"#"),1,0)) | BE8: =IF(OR($D8="",Z8="",14>$F8),0,IF(UPPER(TRIM(Z8))=IFERROR(INDEX(Key!$C$2:$C$263,MATCH($D8*100+14,Key!$G$2:$G$263,0)),"#"),1,0)) | BF8: =IF(OR($D8="",AA8="",15>$F8),0,IF(UPPER(TRIM(AA8))=IFERROR(INDEX(Key!$C$2:$C$263,MATCH($D8*100+15,Key!$G$2:$G$263,0)),"#"),1,0)) | BG8: =IF(OR($D8="",AB8="",16>$F8),0,IF(UPPER(TRIM(AB8))=IFERROR(INDEX(Key!$C$2:$C$263,MATCH($D8*100+16,Key!$G$2:$G$263,0)),"#"),1,0)) | BH8: =IF(OR($D8="",AC8="",17>$F8),0,IF(UPPER(TRIM(AC8))=IFERROR(INDEX(Key!$C$2:$C$263,MATCH($D8*100+17,Key!$G$2:$G$263,0)),"#"),1,0)) | BI8: =IF(OR($D8="",AD8="",18>$F8),0,IF(UPPER(TRIM(AD8))=IFERROR(INDEX(Key!$C$2:$C$263,MATCH($D8*100+18,Key!$G$2:$G$263,0)),"#"),1,0)) | BJ8: =IF(OR($D8="",AE8="",19>$F8),0,IF(UPPER(TRIM(AE8))=IFERROR(INDEX(Key!$C$2:$C$263,MATCH($D8*100+19,Key!$G$2:$G$263,0)),"#"),1,0)) | BK8: =IF(OR($D8="",AF8="",20>$F8),0,IF(UPPER(TRIM(AF8))=IFERROR(INDEX(Key!$C$2:$C$263,MATCH($D8*100+20,Key!$G$2:$G$263,0)),"#"),1,0)) | BL8: =IF(OR($D8="",AG8="",21>$F8),0,IF(UPPER(TRIM(AG8))=IFERROR(INDEX(Key!$C$2:$C$263,MATCH($D8*100+21,Key!$G$2:$G$263,0)),"#"),1,0)) | BM8: =IF(OR($D8="",AH8="",22>$F8),0,IF(UPPER(TRIM(AH8))=IFERROR(INDEX(Key!$C$2:$C$263,MATCH($D8*100+22,Key!$G$2:$G$263,0)),"#"),1,0)) | BN8: =IF(OR($D8="",AI8="",23>$F8),0,IF(UPPER(TRIM(AI8))=IFERROR(INDEX(Key!$C$2:$C$263,MATCH($D8*100+23,Key!$G$2:$G$263,0)),"#"),1,0)) | BO8: =IF(OR($D8="",AJ8="",24>$F8),0,IF(UPPER(TRIM(AJ8))=IFERROR(INDEX(Key!$C$2:$C$263,MATCH($D8*100+24,Key!$G$2:$G$263,0)),"#"),1,0)) | BP8: =IF(OR($D8="",AK8="",25>$F8),0,IF(UPPER(TRIM(AK8))=IFERROR(INDEX(Key!$C$2:$C$263,MATCH($D8*100+25,Key!$G$2:$G$263,0)),"#"),1,0)) | BQ8: =IF(OR($D8="",AL8="",26>$F8),0,IF(UPPER(TRIM(AL8))=IFERROR(INDEX(Key!$C$2:$C$263,MATCH($D8*100+26,Key!$G$2:$G$263,0)),"#"),1,0)) | BR8: =IF(OR($D8="",AM8="",27>$F8),0,IF(UPPER(TRIM(AM8))=IFERROR(INDEX(Key!$C$2:$C$263,MATCH($D8*100+27,Key!$G$2:$G$263,0)),"#"),1,0)) | BS8: =IF(OR($D8="",AN8="",28>$F8),0,IF(UPPER(TRIM(AN8))=IFERROR(INDEX(Key!$C$2:$C$263,MATCH($D8*100+28,Key!$G$2:$G$263,0)),"#"),1,0)) | BT8: =IF(OR($D8="",AO8="",29>$F8),0,IF(UPPER(TRIM(AO8))=IFERROR(INDEX(Key!$C$2:$C$263,MATCH($D8*100+29,Key!$G$2:$G$263,0)),"#"),1,0)) | BU8: =IF(OR($D8="",AP8="",30>$F8),0,IF(UPPER(TRIM(AP8))=IFERROR(INDEX(Key!$C$2:$C$263,MATCH($D8*100+30,Key!$G$2:$G$263,0)),"#"),1,0))
E9: =IF($D9="","",IFERROR(INDEX(Papers!$B$2:$B$12,MATCH($D9,Papers!$A$2:$A$12,0)),"?")) | F9: =IF($D9="","",IFERROR(INDEX(Papers!$C$2:$C$12,MATCH($D9,Papers!$A$2:$A$12,0)),0)) | G9: =IF($D9="","",COUNTIF(M9:AP9,"?*")) | H9: =IF($D9="","",SUM(AR9:BU9)) | I9: =IF($D9="","",G9-H9) | J9: =IF($D9="","",F9-G9) | K9: =IF($D9="","",H9) | L9: =IF($D9="","",IF(F9=0,"",ROUND(H9/F9*100,1))) | AR9: =IF(OR($D9="",M9="",1>$F9),0,IF(UPPER(TRIM(M9))=IFERROR(INDEX(Key!$C$2:$C$263,MATCH($D9*100+1,Key!$G$2:$G$263,0)),"#"),1,0)) | AS9: =IF(OR($D9="",N9="",2>$F9),0,IF(UPPER(TRIM(N9))=IFERROR(INDEX(Key!$C$2:$C$263,MATCH($D9*100+2,Key!$G$2:$G$263,0)),"#"),1,0)) | AT9: =IF(OR($D9="",O9="",3>$F9),0,IF(UPPER(TRIM(O9))=IFERROR(INDEX(Key!$C$2:$C$263,MATCH($D9*100+3,Key!$G$2:$G$263,0)),"#"),1,0)) | AU9: =IF(OR($D9="",P9="",4>$F9),0,IF(UPPER(TRIM(P9))=IFERROR(INDEX(Key!$C$2:$C$263,MATCH($D9*100+4,Key!$G$2:$G$263,0)),"#"),1,0)) | AV9: =IF(OR($D9="",Q9="",5>$F9),0,IF(UPPER(TRIM(Q9))=IFERROR(INDEX(Key!$C$2:$C$263,MATCH($D9*100+5,Key!$G$2:$G$263,0)),"#"),1,0)) | AW9: =IF(OR($D9="",R9="",6>$F9),0,IF(UPPER(TRIM(R9))=IFERROR(INDEX(Key!$C$2:$C$263,MATCH($D9*100+6,Key!$G$2:$G$263,0)),"#"),1,0)) | AX9: =IF(OR($D9="",S9="",7>$F9),0,IF(UPPER(TRIM(S9))=IFERROR(INDEX(Key!$C$2:$C$263,MATCH($D9*100+7,Key!$G$2:$G$263,0)),"#"),1,0)) | AY9: =IF(OR($D9="",T9="",8>$F9),0,IF(UPPER(TRIM(T9))=IFERROR(INDEX(Key!$C$2:$C$263,MATCH($D9*100+8,Key!$G$2:$G$263,0)),"#"),1,0)) | AZ9: =IF(OR($D9="",U9="",9>$F9),0,IF(UPPER(TRIM(U9))=IFERROR(INDEX(Key!$C$2:$C$263,MATCH($D9*100+9,Key!$G$2:$G$263,0)),"#"),1,0)) | BA9: =IF(OR($D9="",V9="",10>$F9),0,IF(UPPER(TRIM(V9))=IFERROR(INDEX(Key!$C$2:$C$263,MATCH($D9*100+10,Key!$G$2:$G$263,0)),"#"),1,0)) | BB9: =IF(OR($D9="",W9="",11>$F9),0,IF(UPPER(TRIM(W9))=IFERROR(INDEX(Key!$C$2:$C$263,MATCH($D9*100+11,Key!$G$2:$G$263,0)),"#"),1,0)) | BC9: =IF(OR($D9="",X9="",12>$F9),0,IF(UPPER(TRIM(X9))=IFERROR(INDEX(Key!$C$2:$C$263,MATCH($D9*100+12,Key!$G$2:$G$263,0)),"#"),1,0)) | BD9: =IF(OR($D9="",Y9="",13>$F9),0,IF(UPPER(TRIM(Y9))=IFERROR(INDEX(Key!$C$2:$C$263,MATCH($D9*100+13,Key!$G$2:$G$263,0)),"#"),1,0)) | BE9: =IF(OR($D9="",Z9="",14>$F9),0,IF(UPPER(TRIM(Z9))=IFERROR(INDEX(Key!$C$2:$C$263,MATCH($D9*100+14,Key!$G$2:$G$263,0)),"#"),1,0)) | BF9: =IF(OR($D9="",AA9="",15>$F9),0,IF(UPPER(TRIM(AA9))=IFERROR(INDEX(Key!$C$2:$C$263,MATCH($D9*100+15,Key!$G$2:$G$263,0)),"#"),1,0)) | BG9: =IF(OR($D9="",AB9="",16>$F9),0,IF(UPPER(TRIM(AB9))=IFERROR(INDEX(Key!$C$2:$C$263,MATCH($D9*100+16,Key!$G$2:$G$263,0)),"#"),1,0)) | BH9: =IF(OR($D9="",AC9="",17>$F9),0,IF(UPPER(TRIM(AC9))=IFERROR(INDEX(Key!$C$2:$C$263,MATCH($D9*100+17,Key!$G$2:$G$263,0)),"#"),1,0)) | BI9: =IF(OR($D9="",AD9="",18>$F9),0,IF(UPPER(TRIM(AD9))=IFERROR(INDEX(Key!$C$2:$C$263,MATCH($D9*100+18,Key!$G$2:$G$263,0)),"#"),1,0)) | BJ9: =IF(OR($D9="",AE9="",19>$F9),0,IF(UPPER(TRIM(AE9))=IFERROR(INDEX(Key!$C$2:$C$263,MATCH($D9*100+19,Key!$G$2:$G$263,0)),"#"),1,0)) | BK9: =IF(OR($D9="",AF9="",20>$F9),0,IF(UPPER(TRIM(AF9))=IFERROR(INDEX(Key!$C$2:$C$263,MATCH($D9*100+20,Key!$G$2:$G$263,0)),"#"),1,0)) | BL9: =IF(OR($D9="",AG9="",21>$F9),0,IF(UPPER(TRIM(AG9))=IFERROR(INDEX(Key!$C$2:$C$263,MATCH($D9*100+21,Key!$G$2:$G$263,0)),"#"),1,0)) | BM9: =IF(OR($D9="",AH9="",22>$F9),0,IF(UPPER(TRIM(AH9))=IFERROR(INDEX(Key!$C$2:$C$263,MATCH($D9*100+22,Key!$G$2:$G$263,0)),"#"),1,0)) | BN9: =IF(OR($D9="",AI9="",23>$F9),0,IF(UPPER(TRIM(AI9))=IFERROR(INDEX(Key!$C$2:$C$263,MATCH($D9*100+23,Key!$G$2:$G$263,0)),"#"),1,0)) | BO9: =IF(OR($D9="",AJ9="",24>$F9),0,IF(UPPER(TRIM(AJ9))=IFERROR(INDEX(Key!$C$2:$C$263,MATCH($D9*100+24,Key!$G$2:$G$263,0)),"#"),1,0)) | BP9: =IF(OR($D9="",AK9="",25>$F9),0,IF(UPPER(TRIM(AK9))=IFERROR(INDEX(Key!$C$2:$C$263,MATCH($D9*100+25,Key!$G$2:$G$263,0)),"#"),1,0)) | BQ9: =IF(OR($D9="",AL9="",26>$F9),0,IF(UPPER(TRIM(AL9))=IFERROR(INDEX(Key!$C$2:$C$263,MATCH($D9*100+26,Key!$G$2:$G$263,0)),"#"),1,0)) | BR9: =IF(OR($D9="",AM9="",27>$F9),0,IF(UPPER(TRIM(AM9))=IFERROR(INDEX(Key!$C$2:$C$263,MATCH($D9*100+27,Key!$G$2:$G$263,0)),"#"),1,0)) | BS9: =IF(OR($D9="",AN9="",28>$F9),0,IF(UPPER(TRIM(AN9))=IFERROR(INDEX(Key!$C$2:$C$263,MATCH($D9*100+28,Key!$G$2:$G$263,0)),"#"),1,0)) | BT9: =IF(OR($D9="",AO9="",29>$F9),0,IF(UPPER(TRIM(AO9))=IFERROR(INDEX(Key!$C$2:$C$263,MATCH($D9*100+29,Key!$G$2:$G$263,0)),"#"),1,0)) | BU9: =IF(OR($D9="",AP9="",30>$F9),0,IF(UPPER(TRIM(AP9))=IFERROR(INDEX(Key!$C$2:$C$263,MATCH($D9*100+30,Key!$G$2:$G$263,0)),"#"),1,0))
E10: =IF($D10="","",IFERROR(INDEX(Papers!$B$2:$B$12,MATCH($D10,Papers!$A$2:$A$12,0)),"?")) | F10: =IF($D10="","",IFERROR(INDEX(Papers!$C$2:$C$12,MATCH($D10,Papers!$A$2:$A$12,0)),0)) | G10: =IF($D10="","",COUNTIF(M10:AP10,"?*")) | H10: =IF($D10="","",SUM(AR10:BU10)) | I10: =IF($D10="","",G10-H10) | J10: =IF($D10="","",F10-G10) | K10: =IF($D10="","",H10) | L10: =IF($D10="","",IF(F10=0,"",ROUND(H10/F10*100,1))) | AR10: =IF(OR($D10="",M10="",1>$F10),0,IF(UPPER(TRIM(M10))=IFERROR(INDEX(Key!$C$2:$C$263,MATCH($D10*100+1,Key!$G$2:$G$263,0)),"#"),1,0)) | AS10: =IF(OR($D10="",N10="",2>$F10),0,IF(UPPER(TRIM(N10))=IFERROR(INDEX(Key!$C$2:$C$263,MATCH($D10*100+2,Key!$G$2:$G$263,0)),"#"),1,0)) | AT10: =IF(OR($D10="",O10="",3>$F10),0,IF(UPPER(TRIM(O10))=IFERROR(INDEX(Key!$C$2:$C$263,MATCH($D10*100+3,Key!$G$2:$G$263,0)),"#"),1,0)) | AU10: =IF(OR($D10="",P10="",4>$F10),0,IF(UPPER(TRIM(P10))=IFERROR(INDEX(Key!$C$2:$C$263,MATCH($D10*100+4,Key!$G$2:$G$263,0)),"#"),1,0)) | AV10: =IF(OR($D10="",Q10="",5>$F10),0,IF(UPPER(TRIM(Q10))=IFERROR(INDEX(Key!$C$2:$C$263,MATCH($D10*100+5,Key!$G$2:$G$263,0)),"#"),1,0)) | AW10: =IF(OR($D10="",R10="",6>$F10),0,IF(UPPER(TRIM(R10))=IFERROR(INDEX(Key!$C$2:$C$263,MATCH($D10*100+6,Key!$G$2:$G$263,0)),"#"),1,0)) | AX10: =IF(OR($D10="",S10="",7>$F10),0,IF(UPPER(TRIM(S10))=IFERROR(INDEX(Key!$C$2:$C$263,MATCH($D10*100+7,Key!$G$2:$G$263,0)),"#"),1,0)) | AY10: =IF(OR($D10="",T10="",8>$F10),0,IF(UPPER(TRIM(T10))=IFERROR(INDEX(Key!$C$2:$C$263,MATCH($D10*100+8,Key!$G$2:$G$263,0)),"#"),1,0)) | AZ10: =IF(OR($D10="",U10="",9>$F10),0,IF(UPPER(TRIM(U10))=IFERROR(INDEX(Key!$C$2:$C$263,MATCH($D10*100+9,Key!$G$2:$G$263,0)),"#"),1,0)) | BA10: =IF(OR($D10="",V10="",10>$F10),0,IF(UPPER(TRIM(V10))=IFERROR(INDEX(Key!$C$2:$C$263,MATCH($D10*100+10,Key!$G$2:$G$263,0)),"#"),1,0)) | BB10: =IF(OR($D10="",W10="",11>$F10),0,IF(UPPER(TRIM(W10))=IFERROR(INDEX(Key!$C$2:$C$263,MATCH($D10*100+11,Key!$G$2:$G$263,0)),"#"),1,0)) | BC10: =IF(OR($D10="",X10="",12>$F10),0,IF(UPPER(TRIM(X10))=IFERROR(INDEX(Key!$C$2:$C$263,MATCH($D10*100+12,Key!$G$2:$G$263,0)),"#"),1,0)) | BD10: =IF(OR($D10="",Y10="",13>$F10),0,IF(UPPER(TRIM(Y10))=IFERROR(INDEX(Key!$C$2:$C$263,MATCH($D10*100+13,Key!$G$2:$G$263,0)),"#"),1,0)) | BE10: =IF(OR($D10="",Z10="",14>$F10),0,IF(UPPER(TRIM(Z10))=IFERROR(INDEX(Key!$C$2:$C$263,MATCH($D10*100+14,Key!$G$2:$G$263,0)),"#"),1,0)) | BF10: =IF(OR($D10="",AA10="",15>$F10),0,IF(UPPER(TRIM(AA10))=IFERROR(INDEX(Key!$C$2:$C$263,MATCH($D10*100+15,Key!$G$2:$G$263,0)),"#"),1,0)) | BG10: =IF(OR($D10="",AB10="",16>$F10),0,IF(UPPER(TRIM(AB10))=IFERROR(INDEX(Key!$C$2:$C$263,MATCH($D10*100+16,Key!$G$2:$G$263,0)),"#"),1,0)) | BH10: =IF(OR($D10="",AC10="",17>$F10),0,IF(UPPER(TRIM(AC10))=IFERROR(INDEX(Key!$C$2:$C$263,MATCH($D10*100+17,Key!$G$2:$G$263,0)),"#"),1,0)) | BI10: =IF(OR($D10="",AD10="",18>$F10),0,IF(UPPER(TRIM(AD10))=IFERROR(INDEX(Key!$C$2:$C$263,MATCH($D10*100+18,Key!$G$2:$G$263,0)),"#"),1,0)) | BJ10: =IF(OR($D10="",AE10="",19>$F10),0,IF(UPPER(TRIM(AE10))=IFERROR(INDEX(Key!$C$2:$C$263,MATCH($D10*100+19,Key!$G$2:$G$263,0)),"#"),1,0)) | BK10: =IF(OR($D10="",AF10="",20>$F10),0,IF(UPPER(TRIM(AF10))=IFERROR(INDEX(Key!$C$2:$C$263,MATCH($D10*100+20,Key!$G$2:$G$263,0)),"#"),1,0)) | BL10: =IF(OR($D10="",AG10="",21>$F10),0,IF(UPPER(TRIM(AG10))=IFERROR(INDEX(Key!$C$2:$C$263,MATCH($D10*100+21,Key!$G$2:$G$263,0)),"#"),1,0)) | BM10: =IF(OR($D10="",AH10="",22>$F10),0,IF(UPPER(TRIM(AH10))=IFERROR(INDEX(Key!$C$2:$C$263,MATCH($D10*100+22,Key!$G$2:$G$263,0)),"#"),1,0)) | BN10: =IF(OR($D10="",AI10="",23>$F10),0,IF(UPPER(TRIM(AI10))=IFERROR(INDEX(Key!$C$2:$C$263,MATCH($D10*100+23,Key!$G$2:$G$263,0)),"#"),1,0)) | BO10: =IF(OR($D10="",AJ10="",24>$F10),0,IF(UPPER(TRIM(AJ10))=IFERROR(INDEX(Key!$C$2:$C$263,MATCH($D10*100+24,Key!$G$2:$G$263,0)),"#"),1,0)) | BP10: =IF(OR($D10="",AK10="",25>$F10),0,IF(UPPER(TRIM(AK10))=IFERROR(INDEX(Key!$C$2:$C$263,MATCH($D10*100+25,Key!$G$2:$G$263,0)),"#"),1,0)) | BQ10: =IF(OR($D10="",AL10="",26>$F10),0,IF(UPPER(TRIM(AL10))=IFERROR(INDEX(Key!$C$2:$C$263,MATCH($D10*100+26,Key!$G$2:$G$263,0)),"#"),1,0)) | BR10: =IF(OR($D10="",AM10="",27>$F10),0,IF(UPPER(TRIM(AM10))=IFERROR(INDEX(Key!$C$2:$C$263,MATCH($D10*100+27,Key!$G$2:$G$263,0)),"#"),1,0)) | BS10: =IF(OR($D10="",AN10="",28>$F10),0,IF(UPPER(TRIM(AN10))=IFERROR(INDEX(Key!$C$2:$C$263,MATCH($D10*100+28,Key!$G$2:$G$263,0)),"#"),1,0)) | BT10: =IF(OR($D10="",AO10="",29>$F10),0,IF(UPPER(TRIM(AO10))=IFERROR(INDEX(Key!$C$2:$C$263,MATCH($D10*100+29,Key!$G$2:$G$263,0)),"#"),1,0)) | BU10: =IF(OR($D10="",AP10="",30>$F10),0,IF(UPPER(TRIM(AP10))=IFERROR(INDEX(Key!$C$2:$C$263,MATCH($D10*100+30,Key!$G$2:$G$263,0)),"#"),1,0))
E11: =IF($D11="","",IFERROR(INDEX(Papers!$B$2:$B$12,MATCH($D11,Papers!$A$2:$A$12,0)),"?")) | F11: =IF($D11="","",IFERROR(INDEX(Papers!$C$2:$C$12,MATCH($D11,Papers!$A$2:$A$12,0)),0)) | G11: =IF($D11="","",COUNTIF(M11:AP11,"?*")) | H11: =IF($D11="","",SUM(AR11:BU11)) | I11: =IF($D11="","",G11-H11) | J11: =IF($D11="","",F11-G11) | K11: =IF($D11="","",H11) | L11: =IF($D11="","",IF(F11=0,"",ROUND(H11/F11*100,1))) | AR11: =IF(OR($D11="",M11="",1>$F11),0,IF(UPPER(TRIM(M11))=IFERROR(INDEX(Key!$C$2:$C$263,MATCH($D11*100+1,Key!$G$2:$G$263,0)),"#"),1,0)) | AS11: =IF(OR($D11="",N11="",2>$F11),0,IF(UPPER(TRIM(N11))=IFERROR(INDEX(Key!$C$2:$C$263,MATCH($D11*100+2,Key!$G$2:$G$263,0)),"#"),1,0)) | AT11: =IF(OR($D11="",O11="",3>$F11),0,IF(UPPER(TRIM(O11))=IFERROR(INDEX(Key!$C$2:$C$263,MATCH($D11*100+3,Key!$G$2:$G$263,0)),"#"),1,0)) | AU11: =IF(OR($D11="",P11="",4>$F11),0,IF(UPPER(TRIM(P11))=IFERROR(INDEX(Key!$C$2:$C$263,MATCH($D11*100+4,Key!$G$2:$G$263,0)),"#"),1,0)) | AV11: =IF(OR($D11="",Q11="",5>$F11),0,IF(UPPER(TRIM(Q11))=IFERROR(INDEX(Key!$C$2:$C$263,MATCH($D11*100+5,Key!$G$2:$G$263,0)),"#"),1,0)) | AW11: =IF(OR($D11="",R11="",6>$F11),0,IF(UPPER(TRIM(R11))=IFERROR(INDEX(Key!$C$2:$C$263,MATCH($D11*100+6,Key!$G$2:$G$263,0)),"#"),1,0)) | AX11: =IF(OR($D11="",S11="",7>$F11),0,IF(UPPER(TRIM(S11))=IFERROR(INDEX(Key!$C$2:$C$263,MATCH($D11*100+7,Key!$G$2:$G$263,0)),"#"),1,0)) | AY11: =IF(OR($D11="",T11="",8>$F11),0,IF(UPPER(TRIM(T11))=IFERROR(INDEX(Key!$C$2:$C$263,MATCH($D11*100+8,Key!$G$2:$G$263,0)),"#"),1,0)) | AZ11: =IF(OR($D11="",U11="",9>$F11),0,IF(UPPER(TRIM(U11))=IFERROR(INDEX(Key!$C$2:$C$263,MATCH($D11*100+9,Key!$G$2:$G$263,0)),"#"),1,0)) | BA11: =IF(OR($D11="",V11="",10>$F11),0,IF(UPPER(TRIM(V11))=IFERROR(INDEX(Key!$C$2:$C$263,MATCH($D11*100+10,Key!$G$2:$G$263,0)),"#"),1,0)) | BB11: =IF(OR($D11="",W11="",11>$F11),0,IF(UPPER(TRIM(W11))=IFERROR(INDEX(Key!$C$2:$C$263,MATCH($D11*100+11,Key!$G$2:$G$263,0)),"#"),1,0)) | BC11: =IF(OR($D11="",X11="",12>$F11),0,IF(UPPER(TRIM(X11))=IFERROR(INDEX(Key!$C$2:$C$263,MATCH($D11*100+12,Key!$G$2:$G$263,0)),"#"),1,0)) | BD11: =IF(OR($D11="",Y11="",13>$F11),0,IF(UPPER(TRIM(Y11))=IFERROR(INDEX(Key!$C$2:$C$263,MATCH($D11*100+13,Key!$G$2:$G$263,0)),"#"),1,0)) | BE11: =IF(OR($D11="",Z11="",14>$F11),0,IF(UPPER(TRIM(Z11))=IFERROR(INDEX(Key!$C$2:$C$263,MATCH($D11*100+14,Key!$G$2:$G$263,0)),"#"),1,0)) | BF11: =IF(OR($D11="",AA11="",15>$F11),0,IF(UPPER(TRIM(AA11))=IFERROR(INDEX(Key!$C$2:$C$263,MATCH($D11*100+15,Key!$G$2:$G$263,0)),"#"),1,0)) | BG11: =IF(OR($D11="",AB11="",16>$F11),0,IF(UPPER(TRIM(AB11))=IFERROR(INDEX(Key!$C$2:$C$263,MATCH($D11*100+16,Key!$G$2:$G$263,0)),"#"),1,0)) | BH11: =IF(OR($D11="",AC11="",17>$F11),0,IF(UPPER(TRIM(AC11))=IFERROR(INDEX(Key!$C$2:$C$263,MATCH($D11*100+17,Key!$G$2:$G$263,0)),"#"),1,0)) | BI11: =IF(OR($D11="",AD11="",18>$F11),0,IF(UPPER(TRIM(AD11))=IFERROR(INDEX(Key!$C$2:$C$263,MATCH($D11*100+18,Key!$G$2:$G$263,0)),"#"),1,0)) | BJ11: =IF(OR($D11="",AE11="",19>$F11),0,IF(UPPER(TRIM(AE11))=IFERROR(INDEX(Key!$C$2:$C$263,MATCH($D11*100+19,Key!$G$2:$G$263,0)),"#"),1,0)) | BK11: =IF(OR($D11="",AF11="",20>$F11),0,IF(UPPER(TRIM(AF11))=IFERROR(INDEX(Key!$C$2:$C$263,MATCH($D11*100+20,Key!$G$2:$G$263,0)),"#"),1,0)) | BL11: =IF(OR($D11="",AG11="",21>$F11),0,IF(UPPER(TRIM(AG11))=IFERROR(INDEX(Key!$C$2:$C$263,MATCH($D11*100+21,Key!$G$2:$G$263,0)),"#"),1,0)) | BM11: =IF(OR($D11="",AH11="",22>$F11),0,IF(UPPER(TRIM(AH11))=IFERROR(INDEX(Key!$C$2:$C$263,MATCH($D11*100+22,Key!$G$2:$G$263,0)),"#"),1,0)) | BN11: =IF(OR($D11="",AI11="",23>$F11),0,IF(UPPER(TRIM(AI11))=IFERROR(INDEX(Key!$C$2:$C$263,MATCH($D11*100+23,Key!$G$2:$G$263,0)),"#"),1,0)) | BO11: =IF(OR($D11="",AJ11="",24>$F11),0,IF(UPPER(TRIM(AJ11))=IFERROR(INDEX(Key!$C$2:$C$263,MATCH($D11*100+24,Key!$G$2:$G$263,0)),"#"),1,0)) | BP11: =IF(OR($D11="",AK11="",25>$F11),0,IF(UPPER(TRIM(AK11))=IFERROR(INDEX(Key!$C$2:$C$263,MATCH($D11*100+25,Key!$G$2:$G$263,0)),"#"),1,0)) | BQ11: =IF(OR($D11="",AL11="",26>$F11),0,IF(UPPER(TRIM(AL11))=IFERROR(INDEX(Key!$C$2:$C$263,MATCH($D11*100+26,Key!$G$2:$G$263,0)),"#"),1,0)) | BR11: =IF(OR($D11="",AM11="",27>$F11),0,IF(UPPER(TRIM(AM11))=IFERROR(INDEX(Key!$C$2:$C$263,MATCH($D11*100+27,Key!$G$2:$G$263,0)),"#"),1,0)) | BS11: =IF(OR($D11="",AN11="",28>$F11),0,IF(UPPER(TRIM(AN11))=IFERROR(INDEX(Key!$C$2:$C$263,MATCH($D11*100+28,Key!$G$2:$G$263,0)),"#"),1,0)) | BT11: =IF(OR($D11="",AO11="",29>$F11),0,IF(UPPER(TRIM(AO11))=IFERROR(INDEX(Key!$C$2:$C$263,MATCH($D11*100+29,Key!$G$2:$G$263,0)),"#"),1,0)) | BU11: =IF(OR($D11="",AP11="",30>$F11),0,IF(UPPER(TRIM(AP11))=IFERROR(INDEX(Key!$C$2:$C$263,MATCH($D11*100+30,Key!$G$2:$G$263,0)),"#"),1,0))
